[2025-05-18T07:49:39.685+0000] {taskinstance.py:1956} INFO - Dependencies all met for dep_context=non-requeueable deps ti=<TaskInstance: flight_price_pipeline.ingest_data manual__2025-05-18T07:49:38.356852+00:00 [queued]>
[2025-05-18T07:49:39.695+0000] {taskinstance.py:1956} INFO - Dependencies all met for dep_context=requeueable deps ti=<TaskInstance: flight_price_pipeline.ingest_data manual__2025-05-18T07:49:38.356852+00:00 [queued]>
[2025-05-18T07:49:39.696+0000] {taskinstance.py:2170} INFO - Starting attempt 1 of 2
[2025-05-18T07:49:39.714+0000] {taskinstance.py:2191} INFO - Executing <Task(PythonOperator): ingest_data> on 2025-05-18 07:49:38.356852+00:00
[2025-05-18T07:49:39.721+0000] {standard_task_runner.py:60} INFO - Started process 436 to run task
[2025-05-18T07:49:39.725+0000] {standard_task_runner.py:87} INFO - Running: ['***', 'tasks', 'run', 'flight_price_pipeline', 'ingest_data', 'manual__2025-05-18T07:49:38.356852+00:00', '--job-id', '6', '--raw', '--subdir', 'DAGS_FOLDER/flight_price_.py', '--cfg-path', '/tmp/tmp9ccn6hiz']
[2025-05-18T07:49:39.728+0000] {standard_task_runner.py:88} INFO - Job 6: Subtask ingest_data
[2025-05-18T07:49:39.790+0000] {task_command.py:423} INFO - Running <TaskInstance: flight_price_pipeline.ingest_data manual__2025-05-18T07:49:38.356852+00:00 [running]> on host d05befceb79d
[2025-05-18T07:49:39.903+0000] {taskinstance.py:2480} INFO - Exporting env vars: AIRFLOW_CTX_DAG_OWNER='***' AIRFLOW_CTX_DAG_ID='flight_price_pipeline' AIRFLOW_CTX_TASK_ID='ingest_data' AIRFLOW_CTX_EXECUTION_DATE='2025-05-18T07:49:38.356852+00:00' AIRFLOW_CTX_TRY_NUMBER='1' AIRFLOW_CTX_DAG_RUN_ID='manual__2025-05-18T07:49:38.356852+00:00'
[2025-05-18T07:49:39.915+0000] {taskinstance.py:2698} ERROR - Task failed with exception
Traceback (most recent call last):
  File "/home/airflow/.local/lib/python3.8/site-packages/airflow/models/taskinstance.py", line 433, in _execute_task
    result = execute_callable(context=context, **execute_callable_kwargs)
  File "/home/airflow/.local/lib/python3.8/site-packages/airflow/operators/python.py", line 199, in execute
    return_value = self.execute_callable()
  File "/home/airflow/.local/lib/python3.8/site-packages/airflow/operators/python.py", line 216, in execute_callable
    return self.python_callable(*self.op_args, **self.op_kwargs)
  File "/opt/airflow/dags/flight_price_.py", line 8, in ingest_data
    from scripts.data_ingestion import ingest_data
ModuleNotFoundError: No module named 'scripts.data_ingestion'
[2025-05-18T07:49:39.935+0000] {taskinstance.py:1138} INFO - Marking task as UP_FOR_RETRY. dag_id=flight_price_pipeline, task_id=ingest_data, execution_date=20250518T074938, start_date=20250518T074939, end_date=20250518T074939
[2025-05-18T07:49:39.950+0000] {standard_task_runner.py:107} ERROR - Failed to execute job 6 for task ingest_data (No module named 'scripts.data_ingestion'; 436)
[2025-05-18T07:49:39.981+0000] {local_task_job_runner.py:234} INFO - Task exited with return code 1
[2025-05-18T07:49:40.018+0000] {taskinstance.py:3280} INFO - 0 downstream tasks scheduled from follow-on schedule check
